Workbook

Sheet MAR 2026
A1: ORDEM | B1: UNIDADES | C1: FILIAL | D1: CR | E1: PROJETO | F1: Nº CARTÃO | G1: MALOTE/POSTAGEM | H1: VALOR | I1: VALOR VSC PERCURSO | J1: VALOR TOTAL | K1: REGIONAIS/GEREX | L1: DESCONTO | M1: TOTAL CONTRATO
A2: 2 | B2: FM516 - Videira | C2: 516 | D2: 8243 | E2: 25318 | F2: 336216 | G2: Malote | H2: 182.56 | I2: 49.92 | J2: =SUM(H2+I2) -> 232.48 | K2: =_xlfn.XLOOKUP(C2,'REGIONAIS-GEREX'!$C$3:$C$445,'REGIONAIS-GEREX'!$A$3:$A$445,"") -> GEFAN - Centro Norte e Centro Oeste | M2: =Tabela2[[#This Row],[VALOR VSC PERCURSO]]+Tabela2[[#This Row],[VALOR ]] -> 232.48
A3: 4 | B3: FM516 - Videira | F3: 336217 | G3: Malote | H3: 269.75 | I3: 427.69 | K3: =_xlfn.XLOOKUP(C3,'REGIONAIS-GEREX'!$C$3:$C$445,'REGIONAIS-GEREX'!$A$3:$A$445," ") | M3: =Tabela2[[#This Row],[VALOR VSC PERCURSO]]+Tabela2[[#This Row],[VALOR ]] -> 697.44
A4: 5 | B4: SESI - UOS - Brusque | C4: 203 | D4: 8144 | E4: 25318 | F4: 336217 | G4: Malote | H4: =H3/2 -> 134.875 | I4: =$I$3/2 -> 213.845 | J4: =SUM(H4+I4) -> 348.72 | K4: =_xlfn.XLOOKUP(C4,'REGIONAIS-GEREX'!$C$3:$C$445,'REGIONAIS-GEREX'!$A$3:$A$445," ") -> Vale do Itajaí Mirim e Foz do Rio Itajaí | M4: =Tabela2[[#This Row],[VALOR VSC PERCURSO]]+Tabela2[[#This Row],[VALOR ]] -> 348.72
A5: 6 | B5: SESI - UOS - Itajaí | C5: 211 | D5: 8144 | E5: 25318 | F5: 336217 | G5: Malote | H5: =H3/2 -> 134.875 | I5: =$I$3/2 -> 213.845 | J5: =SUM(H5+I5) -> 348.72 | K5: =_xlfn.XLOOKUP(C5,'REGIONAIS-GEREX'!$C$3:$C$445,'REGIONAIS-GEREX'!$A$3:$A$445," ") -> Vale do Itajaí Mirim e Foz do Rio Itajaí | M5: =Tabela2[[#This Row],[VALOR VSC PERCURSO]]+Tabela2[[#This Row],[VALOR ]] -> 348.72
A6: 7 | B6: SESI - UOS - Lages | C6: 215 | D6: 8144 | E6: 25318 | F6: 336219 | G6: Malote | H6: 0 | I6: 464.96 | J6: =SUM(H6+I6) -> 464.96 | K6: =_xlfn.XLOOKUP(C6,'REGIONAIS-GEREX'!$C$3:$C$445,'REGIONAIS-GEREX'!$A$3:$A$445," ") -> Serra Catarinense | M6: =Tabela2[[#This Row],[VALOR VSC PERCURSO]]+Tabela2[[#This Row],[VALOR ]] -> 464.96
A7: 8 | B7: SESI - UOS - Criciuma -FM506/FM513/FM576 | F7: 336222 | G7: Malote | H7: 360.53 | I7: 801.87 | K7: =_xlfn.XLOOKUP(C7,'REGIONAIS-GEREX'!$C$3:$C$445,'REGIONAIS-GEREX'!$A$3:$A$445," ") | M7: =Tabela2[[#This Row],[VALOR VSC PERCURSO]]+Tabela2[[#This Row],[VALOR ]] -> 1162.4
A8: 9 | B8: SESI - UOS - Criciúma | C8: 208 | D8: 8144 | E8: 25318 | F8: 336222 | G8: Malote | H8: =$H$7/4 -> 90.1325 | I8: =$I$7/4 -> 200.4675 | J8: =SUM(H8+I8) -> 290.6 | K8: =_xlfn.XLOOKUP(C8,'REGIONAIS-GEREX'!$C$3:$C$445,'REGIONAIS-GEREX'!$A$3:$A$445," ") -> Litoral Sul e Sul | M8: =Tabela2[[#This Row],[VALOR VSC PERCURSO]]+Tabela2[[#This Row],[VALOR ]] -> 290.6
A9: 10 | B9: FM506 | C9: 506 | D9: 8243 | E9: 25318 | F9: 336222 | G9: Malote | H9: =$H$7/4 -> 90.1325 | I9: =$I$7/4 -> 200.4675 | J9: =SUM(H9+I9) -> 290.6 | K9: =_xlfn.XLOOKUP(C9,'REGIONAIS-GEREX'!$C$3:$C$445,'REGIONAIS-GEREX'!$A$3:$A$445," ") -> GEFAN - Sul e Sudeste | M9: =Tabela2[[#This Row],[VALOR VSC PERCURSO]]+Tabela2[[#This Row],[VALOR ]] -> 290.6
A10: 11 | B10: FM513 | C10: 513 | D10: 8243 | E10: 25318 | F10: 336222 | G10: Malote | H10: =$H$7/4 -> 90.1325 | I10: =$I$7/4 -> 200.4675 | J10: =SUM(H10+I10) -> 290.6 | K10: =_xlfn.XLOOKUP(C10,'REGIONAIS-GEREX'!$C$3:$C$445,'REGIONAIS-GEREX'!$A$3:$A$445," ") -> GEFAN - Sul e Sudeste | M10: =Tabela2[[#This Row],[VALOR VSC PERCURSO]]+Tabela2[[#This Row],[VALOR ]] -> 290.6
A11: 12 | B11: FM576 | C11: 576 | D11: 8243 | E11: 25318 | F11: 336222 | G11: Malote | H11: =$H$7/4 -> 90.1325 | I11: =$I$7/4 -> 200.4675 | J11: =SUM(H11+I11) -> 290.6 | K11: =_xlfn.XLOOKUP(C11,'REGIONAIS-GEREX'!$C$3:$C$445,'REGIONAIS-GEREX'!$A$3:$A$445," ") -> GEFAN - Sul e Sudeste | M11: =Tabela2[[#This Row],[VALOR VSC PERCURSO]]+Tabela2[[#This Row],[VALOR ]] -> 290.6
A12: 13 | B12: FM582 - Criciúma | C12: 582 | D12: 8243 | E12: 25318 | F12: 336223 | G12: Malote | H12: 199.84 | I12: 32.64 | J12: =SUM(H12+I12) -> 232.48 | K12: =_xlfn.XLOOKUP(C12,'REGIONAIS-GEREX'!$C$3:$C$445,'REGIONAIS-GEREX'!$A$3:$A$445," ") -> GEFAN - Sul e Sudeste | M12: =Tabela2[[#This Row],[VALOR VSC PERCURSO]]+Tabela2[[#This Row],[VALOR ]] -> 232.48
A13: 14 | B13: FM569 - Cocal do Sul | C13: 569 | D13: 8243 | E13: 25318 | F13: 336224 | G13: Malote | H13: 74.94 | I13: 157.54 | J13: =SUM(H13+I13) -> 232.48 | K13: =_xlfn.XLOOKUP(C13,'REGIONAIS-GEREX'!$C$3:$C$445,'REGIONAIS-GEREX'!$A$3:$A$445," ") -> GEFAN - Sul e Sudeste | M13: =Tabela2[[#This Row],[VALOR VSC PERCURSO]]+Tabela2[[#This Row],[VALOR ]] -> 232.48
A14: 15 | B14: FM577 - Ararangua | C14: 577 | D14: 8243 | E14: 25318 | F14: 336225 | G14: Malote | H14: 74.94 | I14: 157.54 | J14: =SUM(H14+I14) -> 232.48 | K14: =_xlfn.XLOOKUP(C14,'REGIONAIS-GEREX'!$C$3:$C$445,'REGIONAIS-GEREX'!$A$3:$A$445," ") -> GEFAN - Sul e Sudeste | M14: =Tabela2[[#This Row],[VALOR VSC PERCURSO]]+Tabela2[[#This Row],[VALOR ]] -> 232.48
A15: 16 | B15: SESI - UOS Blum - FM 546/548/549/550/551/554/596/597/564/905 | F15: 336227 | G15: Malote | H15: 633.87 | I15: 63.57 | K15: =_xlfn.XLOOKUP(C15,'REGIONAIS-GEREX'!$C$3:$C$445,'REGIONAIS-GEREX'!$A$3:$A$445," ") | M15: =Tabela2[[#This Row],[VALOR VSC PERCURSO]]+Tabela2[[#This Row],[VALOR ]] -> 697.44
A16: 17 | B16: FM546 | C16: 546 | D16: 8243 | E16: 25318 | F16: 336227 | G16: Malote | H16: =SUM(H15/11) -> 57.624545 | I16: =$I$15/11 -> 5.7790909 | J16: =SUM(H16+I16) -> 63.403636 | K16: =_xlfn.XLOOKUP(C16,'REGIONAIS-GEREX'!$C$3:$C$445,'REGIONAIS-GEREX'!$A$3:$A$445," ") -> GEFAN - Vale e Foz do Rio Itajaí | M16: =Tabela2[[#This Row],[VALOR VSC PERCURSO]]+Tabela2[[#This Row],[VALOR ]] -> 63.403636
A17: 18 | B17: FM548 | C17: 548 | D17: 8243 | E17: 25318 | F17: 336227 | G17: Malote | H17: =SUM(H15/11) -> 57.624545 | I17: =$I$15/11 -> 5.7790909 | J17: =SUM(H17+I17) -> 63.403636 | K17: =_xlfn.XLOOKUP(C17,'REGIONAIS-GEREX'!$C$3:$C$445,'REGIONAIS-GEREX'!$A$3:$A$445," ") -> GEFAN - Vale e Foz do Rio Itajaí | M17: =Tabela2[[#This Row],[VALOR VSC PERCURSO]]+Tabela2[[#This Row],[VALOR ]] -> 63.403636
A18: 19 | B18: FM549 | C18: 549 | D18: 8243 | E18: 25318 | F18: 336227 | G18: Malote | H18: =SUM(H15/11) -> 57.624545 | I18: =$I$15/11 -> 5.7790909 | J18: =SUM(H18+I18) -> 63.403636 | K18: =_xlfn.XLOOKUP(C18,'REGIONAIS-GEREX'!$C$3:$C$445,'REGIONAIS-GEREX'!$A$3:$A$445," ") -> GEFAN - Vale e Foz do Rio Itajaí | M18: =Tabela2[[#This Row],[VALOR VSC PERCURSO]]+Tabela2[[#This Row],[VALOR ]] -> 63.403636
A19: 20 | B19: FM550 | C19: 550 | D19: 8243 | E19: 25318 | F19: 336227 | G19: Malote | H19: =SUM(H15/11) -> 57.624545 | I19: =$I$15/11 -> 5.7790909 | J19: =SUM(H19+I19) -> 63.403636 | K19: =_xlfn.XLOOKUP(C19,'REGIONAIS-GEREX'!$C$3:$C$445,'REGIONAIS-GEREX'!$A$3:$A$445," ") -> GEFAN - Vale e Foz do Rio Itajaí | M19: =Tabela2[[#This Row],[VALOR VSC PERCURSO]]+Tabela2[[#This Row],[VALOR ]] -> 63.403636
A20: 21 | B20: FM551 | C20: 551 | D20: 8243 | E20: 25318 | F20: 336227 | G20: Malote | H20: =SUM(H15/11) -> 57.624545 | I20: =$I$15/11 -> 5.7790909 | J20: =SUM(H20+I20) -> 63.403636 | K20: =_xlfn.XLOOKUP(C20,'REGIONAIS-GEREX'!$C$3:$C$445,'REGIONAIS-GEREX'!$A$3:$A$445," ") -> GEFAN - Vale e Foz do Rio Itajaí | M20: =Tabela2[[#This Row],[VALOR VSC PERCURSO]]+Tabela2[[#This Row],[VALOR ]] -> 63.403636
A21: 22 | B21: FM554 | C21: 554 | D21: 8243 | E21: 25318 | F21: 336227 | G21: Malote | H21: =SUM(H15/11) -> 57.624545 | I21: =$I$15/11 -> 5.7790909 | J21: =SUM(H21+I21) -> 63.403636 | K21: =_xlfn.XLOOKUP(C21,'REGIONAIS-GEREX'!$C$3:$C$445,'REGIONAIS-GEREX'!$A$3:$A$445," ") -> GEFAN - Vale e Foz do Rio Itajaí | M21: =Tabela2[[#This Row],[VALOR VSC PERCURSO]]+Tabela2[[#This Row],[VALOR ]] -> 63.403636
A22: 23 | B22: FM596 | C22: 596 | D22: 8243 | E22: 25318 | F22: 336227 | G22: Malote | H22: =SUM(H15/11) -> 57.624545 | I22: =$I$15/11 -> 5.7790909 | J22: =SUM(H22+I22) -> 63.403636 | K22: =_xlfn.XLOOKUP(C22,'REGIONAIS-GEREX'!$C$3:$C$445,'REGIONAIS-GEREX'!$A$3:$A$445," ") -> GEFAN - Vale e Foz do Rio Itajaí | M22: =Tabela2[[#This Row],[VALOR VSC PERCURSO]]+Tabela2[[#This Row],[VALOR ]] -> 63.403636
A23: 24 | B23: FM597 | C23: 597 | D23: 8243 | E23: 25318 | F23: 336227 | G23: Malote | H23: =SUM(H15/11) -> 57.624545 | I23: =$I$15/11 -> 5.7790909 | J23: =SUM(H23+I23) -> 63.403636 | K23: =_xlfn.XLOOKUP(C23,'REGIONAIS-GEREX'!$C$3:$C$445,'REGIONAIS-GEREX'!$A$3:$A$445," ") -> GEFAN - Vale e Foz do Rio Itajaí | M23: =Tabela2[[#This Row],[VALOR VSC PERCURSO]]+Tabela2[[#This Row],[VALOR ]] -> 63.403636
A24: 25 | B24: FM564 | C24: 564 | D24: 8243 | E24: 25318 | F24: 336227 | G24: Malote | H24: =SUM(H15/11) -> 57.624545 | I24: =$I$15/11 -> 5.7790909 | J24: =SUM(H24+I24) -> 63.403636 | K24: =_xlfn.XLOOKUP(C24,'REGIONAIS-GEREX'!$C$3:$C$445,'REGIONAIS-GEREX'!$A$3:$A$445," ") -> GEFAN - Vale e Foz do Rio Itajaí | M24: =Tabela2[[#This Row],[VALOR VSC PERCURSO]]+Tabela2[[#This Row],[VALOR ]] -> 63.403636
A25: 26 | B25: FM905 | C25: 905 | D25: 8243 | E25: 25318 | F25: 336227 | G25: Malote | H25: =SUM(H15/11) -> 57.624545 | I25: =$I$15/11 -> 5.7790909 | J25: =SUM(H25+I25) -> 63.403636 | K25: =_xlfn.XLOOKUP(C25,'REGIONAIS-GEREX'!$C$3:$C$445,'REGIONAIS-GEREX'!$A$3:$A$445," ") -> GEFAN - Vale e Foz do Rio Itajaí | M25: =Tabela2[[#This Row],[VALOR VSC PERCURSO]]+Tabela2[[#This Row],[VALOR ]] -> 63.403636
A26: 28 | B26: SESI - UOS - Jaraguá do Sul - FM -S.A | C26: 212 | D26: 8144 | E26: 25318 | F26: 336231 | G26: Malote | H26: 310.11 | I26: 852.29 | J26: =SUM(H26+I26) -> 1162.4 | K26: =_xlfn.XLOOKUP(C26,'REGIONAIS-GEREX'!$C$3:$C$445,'REGIONAIS-GEREX'!$A$3:$A$445," ") -> Planalto Norte e Vale do Itapocu | M26: =Tabela2[[#This Row],[VALOR VSC PERCURSO]]+Tabela2[[#This Row],[VALOR ]] -> 1162.4
A27: 29 | B27: FM515 - Caçador | C27: 515 | D27: 8243 | E27: 25318 | F27: 336234 | G27: Malote | H27: 49.96 | I27: 182.52 | J27: =SUM(H27+I27) -> 232.48 | K27: =_xlfn.XLOOKUP(C27,'REGIONAIS-GEREX'!$C$3:$C$445,'REGIONAIS-GEREX'!$A$3:$A$445," ") -> GEFAN - Centro Norte e Centro Oeste | M27: =Tabela2[[#This Row],[VALOR VSC PERCURSO]]+Tabela2[[#This Row],[VALOR ]] -> 232.48
A28: 30 | B28: SESI - UOS - Videira | C28: 223 | D28: 8144 | E28: 25318 | F28: 336236 | G28: Malote | H28: 153.48 | I28: 311.48 | J28: =SUM(H28+I28) -> 464.96 | K28: =_xlfn.XLOOKUP(C28,'REGIONAIS-GEREX'!$C$3:$C$445,'REGIONAIS-GEREX'!$A$3:$A$445," ") -> Centro Norte | M28: =Tabela2[[#This Row],[VALOR VSC PERCURSO]]+Tabela2[[#This Row],[VALOR ]] -> 464.96
A29: 31 | B29: FM522 - Fraiburgo | C29: 522 | D29: 8243 | E29: 25318 | F29: 336237 | G29: Malote | H29: 187.11 | I29: 45.37 | J29: =SUM(H29+I29) -> 232.48 | K29: =_xlfn.XLOOKUP(C29,'REGIONAIS-GEREX'!$C$3:$C$445,'REGIONAIS-GEREX'!$A$3:$A$445," ") -> GEFAN - Centro Norte e Centro Oeste | M29: =Tabela2[[#This Row],[VALOR VSC PERCURSO]]+Tabela2[[#This Row],[VALOR ]] -> 232.48
A30: 32 | B30: FM925 - CAPINZAL | C30: 925 | D30: 8243 | E30: 25318 | F30: 10437623 | G30: Malote | H30: 153.96 | I30: 78.52 | J30: =SUM(H30+I30) -> 232.48 | K30: =_xlfn.XLOOKUP(C30,'REGIONAIS-GEREX'!$C$3:$C$445,'REGIONAIS-GEREX'!$A$3:$A$445," ") -> GEFAN - Centro Norte e Centro Oeste | M30: =Tabela2[[#This Row],[VALOR VSC PERCURSO]]+Tabela2[[#This Row],[VALOR ]] -> 232.48
A31: 33 | B31: FM 542 - BRAÇO DO NORTE | C31: 542 | D31: 8243 | E31: 25318 | F31: 10437751 | G31: Malote | H31: 104 | I31: 128.48 | J31: =SUM(H31+I31) -> 232.48 | K31: =_xlfn.XLOOKUP(C31,'REGIONAIS-GEREX'!$C$3:$C$445,'REGIONAIS-GEREX'!$A$3:$A$445," ") -> GEFAN - Sul e Sudeste | M31: =Tabela2[[#This Row],[VALOR VSC PERCURSO]]+Tabela2[[#This Row],[VALOR ]] -> 232.48
A32: 34 | B32: SESI - UOS 207 - Concórdia FM 510/587/SA807 | F32: 336263 | G32: Malote | H32: 604.78 | I32: 0 | K32: =_xlfn.XLOOKUP(C32,'REGIONAIS-GEREX'!$C$3:$C$445,'REGIONAIS-GEREX'!$A$3:$A$445," ") | M32: =Tabela2[[#This Row],[VALOR VSC PERCURSO]]+Tabela2[[#This Row],[VALOR ]] -> 604.78
A33: 35 | B33: SESI - 207 - UOS CONCÓRDIA 3% | C33: 207 | D33: 8144 | E33: 25318 | F33: 336263 | G33: Malote | H33: =($H$32/4)*0.97 -> 146.65915 | I33: =($I$32/4)*0.97 -> 0 | J33: =SUM(H33+I33) -> 146.65915 | K33: =_xlfn.XLOOKUP(C33,'REGIONAIS-GEREX'!$C$3:$C$445,'REGIONAIS-GEREX'!$A$3:$A$445," ") -> Alto Uruguai Catarinense e Centro Oeste | M33: =Tabela2[[#This Row],[VALOR VSC PERCURSO]]+Tabela2[[#This Row],[VALOR ]] -> 146.65915
A34: 36 | B34: SESI - 207 - UOS CONCÓRDIA - Fl. 244 3% | C34: 244 | D34: 8154 | E34: 25318 | F34: 336263 | G34: Malote | H34: =($H$32/4)*0.03 -> 4.53585 | I34: =($I$32/4)*0.03 -> 0 | J34: =SUM(H34+I34) -> 4.53585 | K34: =_xlfn.XLOOKUP(C34,'REGIONAIS-GEREX'!$C$3:$C$445,'REGIONAIS-GEREX'!$A$3:$A$445," ") -> Alto Uruguai Catarinense e Centro Oeste | M34: =Tabela2[[#This Row],[VALOR VSC PERCURSO]]+Tabela2[[#This Row],[VALOR ]] -> 4.53585
A35: 37 | B35: SESI - S.A 807 | C35: 807 | D35: 8264 | E35: 25318 | F35: 336263 | G35: Malote | H35: =($H$32/4) -> 151.195 | I35: =($I$32/4) -> 0 | J35: =SUM(H35+I35) -> 151.195 | K35: =_xlfn.XLOOKUP(C35,'REGIONAIS-GEREX'!$C$3:$C$445,'REGIONAIS-GEREX'!$A$3:$A$445," ") -> GEFAN - Centro Norte e Centro Oeste | M35: =Tabela2[[#This Row],[VALOR VSC PERCURSO]]+Tabela2[[#This Row],[VALOR ]] -> 151.195
A36: 38 | B36: FM510 | C36: 510 | D36: 8243 | E36: 25318 | F36: 336263 | G36: Malote | H36: =($H$32/4) -> 151.195 | I36: =($I$32/4) -> 0 | J36: =SUM(H36+I36) -> 151.195 | K36: =_xlfn.XLOOKUP(C36,'REGIONAIS-GEREX'!$C$3:$C$445,'REGIONAIS-GEREX'!$A$3:$A$445," ") -> GEFAN - Centro Norte e Centro Oeste | M36: =Tabela2[[#This Row],[VALOR VSC PERCURSO]]+Tabela2[[#This Row],[VALOR ]] -> 151.195
A37: 39 | B37: FM587 | C37: 587 | D37: 8243 | E37: 25318 | F37: 336263 | G37: Malote | H37: =($H$32/4) -> 151.195 | I37: =($I$32/4) -> 0 | J37: =SUM(H37+I37) -> 151.195 | K37: =_xlfn.XLOOKUP(C37,'REGIONAIS-GEREX'!$C$3:$C$445,'REGIONAIS-GEREX'!$A$3:$A$445," ") -> GEFAN - Centro Norte e Centro Oeste | M37: =Tabela2[[#This Row],[VALOR VSC PERCURSO]]+Tabela2[[#This Row],[VALOR ]] -> 151.195
A38: 40 | B38: FM534 - Ibirama | C38: 534 | D38: 8243 | E38: 25318 | F38: 336148 | G38: Malote | H38: 74.94 | I38: 225.38 | J38: =SUM(H38+I38) -> 300.32 | K38: =_xlfn.XLOOKUP(C38,'REGIONAIS-GEREX'!$C$3:$C$445,'REGIONAIS-GEREX'!$A$3:$A$445," ") -> GEFAN - Alto Vale e Serra | M38: =Tabela2[[#This Row],[VALOR VSC PERCURSO]]+Tabela2[[#This Row],[VALOR ]] -> 300.32
A39: 41 | B39: SESI - UOS-Joinv-FM 556/557/559/560/562/563/574/586/592/599 | F39: 336152 | G39: Malote | H39: 613.45 | I39: 888.15 | K39: =_xlfn.XLOOKUP(C39,'REGIONAIS-GEREX'!$C$3:$C$445,'REGIONAIS-GEREX'!$A$3:$A$445," ") | M39: =Tabela2[[#This Row],[VALOR VSC PERCURSO]]+Tabela2[[#This Row],[VALOR ]] -> 1501.6
A40: 42 | B40: SESI - UOS JOINVILLE | C40: 214 | D40: 8144 | E40: 25318 | F40: 336152 | G40: Malote | H40: =$H$39/10 -> 61.345 | I40: =$I$39/10 -> 88.815 | J40: =SUM(H40+I40) -> 150.16 | K40: =_xlfn.XLOOKUP(C40,'REGIONAIS-GEREX'!$C$3:$C$445,'REGIONAIS-GEREX'!$A$3:$A$445," ") -> Norte Nordeste | M40: =Tabela2[[#This Row],[VALOR VSC PERCURSO]]+Tabela2[[#This Row],[VALOR ]] -> 150.16
...

Sheet rateio
A1: MALOTE/POSTAGEM | B1: FILIAL | C1: CR | D1: PROJETO | E1: TOTAL
A2: SESI | B2: 100 | C2: 7980 | D2: 25318 | E2: 77.27
A3: SESI | B3: 100 | C3: 7980 | D3: 25318 | E3: 333.38
A4: SESI | B4: 100 | C4: 8056 | D4: 25318 | E4: 1767.96
A5: SESI | B5: 203 | C5: 8144 | D5: 25318 | E5: 348.72
A6: SESI | B6: 211 | C6: 8144 | D6: 25318 | E6: 348.72
A7: SESI | B7: 215 | C7: 8144 | D7: 25318 | E7: 464.96
A8: SESI | B8: 208 | C8: 8144 | D8: 25318 | E8: 290.6
A9: SESI | B9: 212 | C9: 8144 | D9: 25318 | E9: 1162.4
A10: SESI | B10: 223 | C10: 8144 | D10: 25318 | E10: 464.96
A11: SESI | B11: 207 | C11: 8144 | D11: 25318 | E11: 146.65915
A12: SESI | B12: 214 | C12: 8144 | D12: 25318 | E12: 150.16
A13: SESI | B13: 222 | C13: 8144 | D13: 25318 | E13: 232.48
... A172: SESI | B172: 100 | C172: 13310 | D172: 25318 | E172: 30.28
E173: =SUM(E2:E172) -> 41036.143
A175: MALOTE/POSTAGEM | B175: FILIAL | C175: CR | D175: PROJETO | E175: TOTAL
A176: SENAI | B176: 0 | C176: 7530 | D176: 25386 | E176: 1010.82
A177: SENAI | B177: 73 | C177: 7638 | D177: 25386 | E177: 1690.15
A178: SENAI | B178: 73 | C178: 7638 | D178: 25386 | E178: 78.39
A179: SENAI | B179: 54 | C179: 7648 | D179: 25386 | E179: 129.88
A180: SENAI | B180: 0 | C180: 7980 | D180: 25386 | E180: 83.05
A181: SENAI | B181: 0 | C181: 8047 | D181: 25386 | E181: 53.15
A182: SENAI | B182: 0 | C182: 8056 | D182: 25386 | E182: 3253.38
A183: SENAI | B183: 94 | C183: 8088 | D183: 25386 | E183: 828.55
A184: SENAI | B184: 94 | C184: 8088 | D184: 25386 | E184: 223.17
A185: SENAI | B185: 94 | C185: 8088 | D185: 25386 | E185: 118.16
A186: SENAI | B186: 15 | C186: 8144 | D186: 25386 | E186: 232.48
A187: SENAI | B187: 22 | C187: 8144 | D187: 25386 | E187: 232.48
... A211: SENAI | B211: 92 | C211: 13316 | D211: 25386 | E211: 1824.31
E212: =SUM(E176:E211) -> 18469.273
A214: MALOTE/POSTAGEM | B214: FILIAL | C214: CR | D214: PROJETO | E214: TOTAL
A215: IEL | B215: 1 | C215: 8056 | D215: 25393 | E215: 29.48
A216: IEL | B216: 6 | C216: 8144 | D216: 25393 | E216: 18.62
A217: IEL | B217: 1 | C217: 12421 | D217: 25393 | E217: 269.73333
E218: =SUM(E215:E217) -> 317.83333
A220: MALOTE/POSTAGEM | B220: FILIAL | C220: CR | D220: PROJETO | E220: TOTAL
A221: FIESC | B221: FIESC | C221: 7980 | D221: 25337 | E221: 34.71
A222: FIESC | B222: FIESC | C222: 8006 | D222: 25337 | E222: 121.04
A223: FIESC | B223: FIESC | C223: 8047 | D223: 25337 | E223: 746.25
A224: FIESC | B224: FIESC | C224: 8056 | D224: 25337 | E224: 10.72
...

Sheet REGIONAIS-GEREX
A2: REGIONAL | B2: FILIAL | C2: CODIGO
A3: Planalto Norte e Vale do Itapocu | B3: 217 - SESI/SC - Mafra | C3: 217
A4: Alto Vale do Itajaí | B4: 219 - SESI/SC - Rio do Sul | C4: 219
A5: Planalto Norte e Vale do Itapocu | B5: 221 - SESI/SC - São Bento do Sul | C5: 221
A6: Sudeste | B6: 209 - SESI/SC - São José | C6: 209
A7: Litoral Sul e Sul | B7: 222 - SESI/SC - Tubarão | C7: 222
A8: Centro Norte | B8: 223 - SESI/SC - Videira | C8: 223
A9: Planalto Norte e Vale do Itapocu | B9: 228 - SESI/SC - São Bento do Sul II | C9: 228
A10: GEFAN - Alto Vale e Serra | B10: 534 - farmaSesi Ibirama | C10: 534
A11: GEFAN - Oeste | B11: 532 - farmaSesi São Miguel do Oeste | C11: 532
A12: GEFAN - Norte - Nordeste / Plan. e Vale | B12: 531 - farmaSesi Canoinhas | C12: 531
A13: GEFAN - Alto Vale e Serra | B13: 530 - farmaSesi Curitibanos | C13: 530
A14: GEFAN - Alto Vale e Serra | B14: 529 - farmaSesi Rio do Sul | C14: 529
... A86: GEFAN - Norte - Nordeste / Plan. e Vale | B86: 512 - farmaSesi São Bento do Sul | C86: 512
A87: SEDE | B87: CIESC | C87: 1.2
A88: SEDE | B88: IEL/SC - Departamento Regional | C88: 1.1.
A89: SEDE | B89: FIESC | C89: 1
A90: Sudeste | B90: SENAI/SC - São José | C90: 2
A91: Litoral Sul e Sul | B91: SENAI/SC - Criciúma | C91: 24
A92: Sudeste | B92: SENAI/SC - Florianópolis | C92: 0
A93: Serra Catarinense | B93: SENAI/SC - Lages | C93: 23
A94: Extremo Oeste e Oeste | B94: SENAI/SC - São Miguel do Oeste | C94: 17
A95: Centro Norte | B95: SENAI/SC - Canoinhas | C95: 20
A96: Planalto Norte e Vale do Itapocu | B96: SENAI/SC - Jaraguá do Sul | C96: 11
A97: Vale do Itajaí Mirim e Foz do Rio Itajaí | B97: SENAI/SC - Itajaí | C97: 7
A98: Extremo Oeste e Oeste | B98: SENAI/SC - Chapecó | C98: 15
A99: Vale do Itajaí Mirim e Foz do Rio Itajaí | B99: SENAI/SC - Brusque | C99: 6
A100: Norte Nordeste | B100: SENAI/SC - Joinville Norte I | C100: 9
... A420: SEDE | B420: SENAI/SC - Direção Regional | C420: 0
A421: SEDE | B421: SESI GEPES | C421: 100.3
A422: SEDE | B422: SESI FAN / ALIMENTAÇÃO | C422: 100.1
A423: SEDE | B423: SESI FAN / FARMACIA | C423: 100.2
A424: SEDE | B424: SESI / SENAI / IEL - COMAR (SESI) | C424: 100.4
A425: SEDE | B425: SESI GECON | C425: 100.5
A426: SEDE | B426: SESI GECON ARE | C426: 100.6
A427: SEDE | B427: SESI GENGE | C427: 100.7
A428: SEDE | B428: SENAI-GEDUP | C428: 0.1
A429: SEDE | B429: SENAI GEPES | C429: 0.2
A430: SEDE | B430: SENAI GECON | C430: 0.3
A431: SEDE | B431: SENAI - GECON ARE | C431: 0.4
...

Sheet EXT. SINTÉTICO
B3: Cartão de Postagem | C3: Valor Líquido(R$)
B4: 336081 | C4: 252.44
B5: 336084 | C5: 132.12
B6: 336091 | C6: 335.56
B7: 336105 | C7: 224.33
B8: 336109 | C8: 307.44
B9: 336116 | C9: 104
B10: 336119 | C10: 348.28
B11: 336120 | C11: 74.94
B12: 336125 | C12: 431.4
B13: 336148 | C13: 74.94
B14: 336152 | C14: 613.45
B15: 336155 | C15: 207.55
... B132: 79859151 | C132: 342.9
C134: 47632.53

Sheet DÉBITO VSC
C3: LANCAMENTOS DE DEBITOS
C4: Descricao | D4: Valor do debito
C5: 336081 | D5: 445
C6: 336084 | D6: 332.84
C7: 336091 | D7: 129.4
C8: 336105 | D8: 473.11
C9: 336109 | D9: 390
C10: 336116 | D10: 128.48
C11: 336119 | D11: 116.68
C12: 336120 | D12: 157.54
C13: 336125 | D13: 33.56
C14: 336148 | D14: 225.38
C15: 336152 | D15: 888.15
C16: 336155 | D16: 257.41
... C60: 10458514 | D60: 7.66
D62: 13999.47

Sheet CRÉDITO
B3: LANCAMENTOS DE CREDITOS
B4: Descricao do credito | C4: Valor do credito
B5: 0067982999 Rest Div Peso-AD121146397BR | C5: 30.26
B6: 0067985807 Rest Div Peso-DA546122667BR | C6: 9.72
B7: TOTAL | C7: =SUM(C5:C6) -> 39.98

Sheet SEDEX REVERSO 
C3: 46052 | D3: 8008 | E3: 8264 | F3: 25318 | G3: 3375889 | H3: ATENISIA OLIVEIRA DA SILVA MELO | I3: 4318628025 | J3: DA546702437BR | K3: 40.72
C4: 46052 | D4: 8019 | E4: 8264 | F4: 25318 | G4: 3376742 | H4: CRISTIANE APARECIDA DOS SANTOS | I4: 4319137270 | J4: DA546763515BR | K4: 43.56
C5: 46055 | D5: 4027 | E5: 8264 | F5: 25318 | G5: 3377830 | H5: MARIA ELIZABEL DUARDO COSTA | I5: 4320354527 | J5: DA546897910BR | K5: 55.09
C6: 46055 | D6: 215 | E6: 12161 | F6: 25318 | G6: 3377924 | H6: CRISTIANE APARECIDA DOS SANTOS | I6: 4320378557 | J6: DA546902265BR | K6: 191.11
C7: 46056 | D7: 471 | E7: 8264 | F7: 25318 | G7: 3378234 | H7: JESIANE DE SOUZA | I7: 4320694814 | J7: DA546925519BR | K7: 70.67
C8: 46056 | D8: 471 | E8: 8264 | F8: 25318 | G8: 3378234 | H8: JESIANE DE SOUZA | I8: 4320696667 | J8: DA546925598BR | K8: 106.28
C9: 46056 | D9: 214 | E9: 12161 | F9: 25318 | G9: 3379019 | H9: MARCOS FELIPE SIQUEIRA | I9: 4321979091 | J9: DA547174793BR | K9: 219.92
C10: 46056 | D10: 214 | E10: 12161 | F10: 25318 | G10: 3379036 | H10: MARCOS FELIPE SIQUEIRA | I10: 4322170285 | J10: DA547180944BR | K10: 381.26
C11: 46059 | D11: 8008 | E11: 8264 | F11: 25318 | G11: 3381127 | H11: ATENISIA OLIVEIRA DA SILVA MELO | I11: 4324830488 | J11: DA547684859BR | K11: 93.26
C12: 46062 | D12: 92 | E12: 13316 | F12: 25386 | G12: 3382731 | H12: CARLOS EDUARDO COLOMBO | I12: 4326258035 | J12: AD090413983BR | K12: 77.2
C13: 46062 | D13: 4081 | E13: 8264 | F13: 25318 | G13: 3382706 | H13: CARINA GUBITOSO | I13: 4326266273 | J13: DA547995119BR | K13: 56.71
C14: 46062 | D14: 94 | E14: 8088 | F14: 25386 | G14: 3382936 | H14: TARLLONE SIRQUEIRA FELISARDO | I14: 4326497584 | J14: AD091584627BR | K14: 118.16
... C43: 46079 | D43: 4007 | E43: 8264 | F43: 25318 | G43: 3395846 | H43: ALANA KUNZ KOZIKOWSK | I43: 4341891715 | J43: DA560923828BR | K43: 86.34
K44: =SUM(K3:K43) -> 7077.21
C47: Coluna1 | D47: Coluna2 | E47: Coluna3 | F47: Coluna4 | G47: Coluna5 | H47: Coluna6 | I47: Coluna7 | J47: Coluna8
C48: 46042 | D48: 94 | E48: 8088 | F48: 25386 | G48: 3368852 | H48: TARLLONE SIRQUEIRA FELISARDO | I48: 4298603995 | J48: AB939906682BR
C49: 46042 | D49: 94 | E49: 8088 | F49: 25386 | G49: 3369127 | H49: TARLLONE SIRQUEIRA FELISARDO | I49: 4299129987 | J49: AB940929442BR
C50: 46044 | D50: 248 | E50: 12161 | F50: 25318 | G50: 3370593 | H50: ANDRESSA ALINE GARBOSSA | I50: 4300757267 | J50: DA545975536BR
C51: 46044 | D51: 4028 | E51: 8264 | F51: 25318 | G51: 3370650 | H51: ALANA KUNZ KOZIKOWSK | I51: 4300762912 | J51: DA545975902BR
C52: 46044 | D52: 8008 | E52: 8264 | F52: 25318 | G52: 3370802 | H52: ATENISIA OLIVEIRA DA SILVA MELO | I52: 4300834401 | J52: DA545979674BR
C53: 46044 | D53: 94 | E53: 8088 | F53: 25386 | G53: 3371145 | H53: TARLLONE SIRQUEIRA FELISARDO | I53: 4301076138 | J53: DA546016270BR
C54: 46044 | D54: 840 | E54: 8264 | F54: 25318 | G54: 3371235 | H54: LUCAS FERREIRA ALVES | I54: 4301123354 | J54: DA546019761BR
C55: 46045 | D55: 215 | E55: 12161 | F55: 25318 | G55: 3371806 | H55: CRISTIANE APARECIDA DOS SANTOS | I55: 4301782144 | J55: DA546122667BR
C56: 46049 | D56: 474 | E56: 8264 | F56: 25318 | G56: 3373844 | H56: DEBORA AUGUSTIN | I56: 4314544221 | J56: DA546379172BR
C57: 46052 | D57: 8008 | E57: 8264 | F57: 25318 | G57: 3375889 | H57: ATENISIA OLIVEIRA DA SILVA MELO | I57: 4318628025 | J57: DA546702437BR
C58: 46052 | D58: 8019 | E58: 8264 | F58: 25318 | G58: 3376742 | H58: CRISTIANE APARECIDA DOS SANTOS | I58: 4319137270 | J58: DA546763515BR
C59: 46055 | D59: 4027 | E59: 8264 | F59: 25318 | G59: 3377830 | H59: MARIA ELIZABEL DUARDO COSTA | I59: 4320354527 | J59: DA546897910BR
... C108: 46080 | D108: 474 | E108: 8264 | F108: 25318 | G108: 3396321 | H108: DEBORA AUGUSTIN | I108: 4342321491 | J108: DA560977548BR
